[2025-10-01T13:58:38.354+0000] {local_task_job_runner.py:120} INFO - ::group::Pre task execution logs
[2025-10-01T13:58:38.372+0000] {taskinstance.py:2076} INFO - Dependencies all met for dep_context=non-requeueable deps ti=<TaskInstance: main.read_data manual__2025-10-01T13:58:13.345522+00:00 [queued]>
[2025-10-01T13:58:38.379+0000] {taskinstance.py:2076} INFO - Dependencies all met for dep_context=requeueable deps ti=<TaskInstance: main.read_data manual__2025-10-01T13:58:13.345522+00:00 [queued]>
[2025-10-01T13:58:38.379+0000] {taskinstance.py:2306} INFO - Starting attempt 1 of 1
[2025-10-01T13:58:38.391+0000] {taskinstance.py:2330} INFO - Executing <Task(PythonOperator): read_data> on 2025-10-01 13:58:13.345522+00:00
[2025-10-01T13:58:38.397+0000] {warnings.py:112} WARNING - /home/***/.local/lib/python3.12/site-packages/***/task/task_runner/standard_task_runner.py:61: DeprecationWarning: This process (pid=4168) is multi-threaded, use of fork() may lead to deadlocks in the child.
  pid = os.fork()

[2025-10-01T13:58:38.398+0000] {standard_task_runner.py:63} INFO - Started process 4169 to run task
[2025-10-01T13:58:38.399+0000] {standard_task_runner.py:90} INFO - Running: ['***', 'tasks', 'run', 'main', 'read_data', 'manual__2025-10-01T13:58:13.345522+00:00', '--job-id', '42', '--raw', '--subdir', 'DAGS_FOLDER/main.py', '--cfg-path', '/tmp/tmpdx50mhf9']
[2025-10-01T13:58:38.400+0000] {standard_task_runner.py:91} INFO - Job 42: Subtask read_data
[2025-10-01T13:58:38.437+0000] {task_command.py:426} INFO - Running <TaskInstance: main.read_data manual__2025-10-01T13:58:13.345522+00:00 [running]> on host 8f02716048bd
[2025-10-01T13:58:38.499+0000] {taskinstance.py:2648} INFO - Exporting env vars: AIRFLOW_CTX_DAG_OWNER='***' AIRFLOW_CTX_DAG_ID='main' AIRFLOW_CTX_TASK_ID='read_data' AIRFLOW_CTX_EXECUTION_DATE='2025-10-01T13:58:13.345522+00:00' AIRFLOW_CTX_TRY_NUMBER='1' AIRFLOW_CTX_DAG_RUN_ID='manual__2025-10-01T13:58:13.345522+00:00'
[2025-10-01T13:58:38.500+0000] {taskinstance.py:430} INFO - ::endgroup::
[2025-10-01T13:58:39.076+0000] {base.py:84} INFO - Using connection ID 'postgres_conn' for task execution.
[2025-10-01T13:58:39.077+0000] {taskinstance.py:441} INFO - ::group::Post task execution logs
[2025-10-01T13:58:39.078+0000] {taskinstance.py:2905} ERROR - Task failed with exception
Traceback (most recent call last):
  File "/home/airflow/.local/lib/python3.12/site-packages/airflow/models/taskinstance.py", line 465, in _execute_task
    result = _execute_callable(context=context, **execute_callable_kwargs)
             ^^^^^^^^^^^^^^^^^^^^^^^^^^^^^^^^^^^^^^^^^^^^^^^^^^^^^^^^^^^^^
  File "/home/airflow/.local/lib/python3.12/site-packages/airflow/models/taskinstance.py", line 432, in _execute_callable
    return execute_callable(context=context, **execute_callable_kwargs)
           ^^^^^^^^^^^^^^^^^^^^^^^^^^^^^^^^^^^^^^^^^^^^^^^^^^^^^^^^^^^^
  File "/home/airflow/.local/lib/python3.12/site-packages/airflow/models/baseoperator.py", line 401, in wrapper
    return func(self, *args, **kwargs)
           ^^^^^^^^^^^^^^^^^^^^^^^^^^^
  File "/home/airflow/.local/lib/python3.12/site-packages/airflow/operators/python.py", line 235, in execute
    return_value = self.execute_callable()
                   ^^^^^^^^^^^^^^^^^^^^^^^
  File "/home/airflow/.local/lib/python3.12/site-packages/airflow/operators/python.py", line 252, in execute_callable
    return self.python_callable(*self.op_args, **self.op_kwargs)
           ^^^^^^^^^^^^^^^^^^^^^^^^^^^^^^^^^^^^^^^^^^^^^^^^^^^^^
  File "/opt/airflow/dags/main.py", line 12, in fetch_data_from_postgres
    df = hook.get_pandas_df(sql)
         ^^^^^^^^^^^^^^^^^^^^^^^
  File "/home/airflow/.local/lib/python3.12/site-packages/airflow/providers/common/sql/hooks/sql.py", line 262, in get_pandas_df
    with closing(self.get_conn()) as conn:
                 ^^^^^^^^^^^^^^^
  File "/home/airflow/.local/lib/python3.12/site-packages/airflow/providers/postgres/hooks/postgres.py", line 175, in get_conn
    self.conn = psycopg2.connect(**conn_args)
                ^^^^^^^^^^^^^^^^^^^^^^^^^^^^^
  File "/home/airflow/.local/lib/python3.12/site-packages/psycopg2/__init__.py", line 122, in connect
    conn = _connect(dsn, connection_factory=connection_factory, **kwasync)
           ^^^^^^^^^^^^^^^^^^^^^^^^^^^^^^^^^^^^^^^^^^^^^^^^^^^^^^^^^^^^^^^
psycopg2.OperationalError: connection to server at "localhost" (127.0.0.1), port 5432 failed: Connection refused
	Is the server running on that host and accepting TCP/IP connections?
connection to server at "localhost" (::1), port 5432 failed: Cannot assign requested address
	Is the server running on that host and accepting TCP/IP connections?

[2025-10-01T13:58:39.087+0000] {taskinstance.py:1206} INFO - Marking task as FAILED. dag_id=main, task_id=read_data, run_id=manual__2025-10-01T13:58:13.345522+00:00, execution_date=20251001T135813, start_date=20251001T135838, end_date=20251001T135839
[2025-10-01T13:58:39.100+0000] {standard_task_runner.py:110} ERROR - Failed to execute job 42 for task read_data (connection to server at "localhost" (127.0.0.1), port 5432 failed: Connection refused
	Is the server running on that host and accepting TCP/IP connections?
connection to server at "localhost" (::1), port 5432 failed: Cannot assign requested address
	Is the server running on that host and accepting TCP/IP connections?
; 4169)
[2025-10-01T13:58:39.135+0000] {local_task_job_runner.py:240} INFO - Task exited with return code 1
[2025-10-01T13:58:39.148+0000] {taskinstance.py:3503} INFO - 0 downstream tasks scheduled from follow-on schedule check
[2025-10-01T13:58:39.151+0000] {local_task_job_runner.py:222} INFO - ::endgroup::
