[2025-10-02T07:47:40.312+0000] {local_task_job_runner.py:120} INFO - ::group::Pre task execution logs
[2025-10-02T07:47:40.333+0000] {taskinstance.py:2076} INFO - Dependencies all met for dep_context=non-requeueable deps ti=<TaskInstance: main.run_pyspark_task manual__2025-10-02T07:47:38.699980+00:00 [queued]>
[2025-10-02T07:47:40.338+0000] {taskinstance.py:2076} INFO - Dependencies all met for dep_context=requeueable deps ti=<TaskInstance: main.run_pyspark_task manual__2025-10-02T07:47:38.699980+00:00 [queued]>
[2025-10-02T07:47:40.339+0000] {taskinstance.py:2306} INFO - Starting attempt 1 of 1
[2025-10-02T07:47:40.347+0000] {taskinstance.py:2330} INFO - Executing <Task(PythonOperator): run_pyspark_task> on 2025-10-02 07:47:38.699980+00:00
[2025-10-02T07:47:40.352+0000] {warnings.py:112} WARNING - /home/***/.local/lib/python3.12/site-packages/***/task/task_runner/standard_task_runner.py:61: DeprecationWarning: This process (pid=63) is multi-threaded, use of fork() may lead to deadlocks in the child.
  pid = os.fork()

[2025-10-02T07:47:40.353+0000] {standard_task_runner.py:63} INFO - Started process 64 to run task
[2025-10-02T07:47:40.353+0000] {standard_task_runner.py:90} INFO - Running: ['***', 'tasks', 'run', 'main', 'run_pyspark_task', 'manual__2025-10-02T07:47:38.699980+00:00', '--job-id', '53', '--raw', '--subdir', 'DAGS_FOLDER/main.py', '--cfg-path', '/tmp/tmpp131vr26']
[2025-10-02T07:47:40.354+0000] {standard_task_runner.py:91} INFO - Job 53: Subtask run_pyspark_task
[2025-10-02T07:47:40.386+0000] {task_command.py:426} INFO - Running <TaskInstance: main.run_pyspark_task manual__2025-10-02T07:47:38.699980+00:00 [running]> on host 62a7c54bc605
[2025-10-02T07:47:40.444+0000] {taskinstance.py:2648} INFO - Exporting env vars: AIRFLOW_CTX_DAG_OWNER='***' AIRFLOW_CTX_DAG_ID='main' AIRFLOW_CTX_TASK_ID='run_pyspark_task' AIRFLOW_CTX_EXECUTION_DATE='2025-10-02T07:47:38.699980+00:00' AIRFLOW_CTX_TRY_NUMBER='1' AIRFLOW_CTX_DAG_RUN_ID='manual__2025-10-02T07:47:38.699980+00:00'
[2025-10-02T07:47:40.445+0000] {taskinstance.py:430} INFO - ::endgroup::
[2025-10-02T07:47:47.789+0000] {taskinstance.py:441} INFO - ::group::Post task execution logs
[2025-10-02T07:47:47.790+0000] {taskinstance.py:2905} ERROR - Task failed with exception
Traceback (most recent call last):
  File "/home/airflow/.local/lib/python3.12/site-packages/airflow/models/taskinstance.py", line 465, in _execute_task
    result = _execute_callable(context=context, **execute_callable_kwargs)
             ^^^^^^^^^^^^^^^^^^^^^^^^^^^^^^^^^^^^^^^^^^^^^^^^^^^^^^^^^^^^^
  File "/home/airflow/.local/lib/python3.12/site-packages/airflow/models/taskinstance.py", line 432, in _execute_callable
    return execute_callable(context=context, **execute_callable_kwargs)
           ^^^^^^^^^^^^^^^^^^^^^^^^^^^^^^^^^^^^^^^^^^^^^^^^^^^^^^^^^^^^
  File "/home/airflow/.local/lib/python3.12/site-packages/airflow/models/baseoperator.py", line 401, in wrapper
    return func(self, *args, **kwargs)
           ^^^^^^^^^^^^^^^^^^^^^^^^^^^
  File "/home/airflow/.local/lib/python3.12/site-packages/airflow/operators/python.py", line 235, in execute
    return_value = self.execute_callable()
                   ^^^^^^^^^^^^^^^^^^^^^^^
  File "/home/airflow/.local/lib/python3.12/site-packages/airflow/operators/python.py", line 252, in execute_callable
    return self.python_callable(*self.op_args, **self.op_kwargs)
           ^^^^^^^^^^^^^^^^^^^^^^^^^^^^^^^^^^^^^^^^^^^^^^^^^^^^^
  File "/opt/airflow/dags/main.py", line 43, in run_spark_job
    .csv("/opt/airflow/tmp/russian_houses.csv"))
     ^^^^^^^^^^^^^^^^^^^^^^^^^^^^^^^^^^^^^^^^^^
  File "/home/airflow/.local/lib/python3.12/site-packages/pyspark/sql/readwriter.py", line 727, in csv
    return self._df(self._jreader.csv(self._spark._sc._jvm.PythonUtils.toSeq(path)))
                    ^^^^^^^^^^^^^^^^^^^^^^^^^^^^^^^^^^^^^^^^^^^^^^^^^^^^^^^^^^^^^^^
  File "/opt/spark/spark-3.4.2-bin-hadoop3/python/lib/py4j-0.10.9.7-src.zip/py4j/java_gateway.py", line 1322, in __call__
    return_value = get_return_value(
                   ^^^^^^^^^^^^^^^^^
  File "/home/airflow/.local/lib/python3.12/site-packages/pyspark/errors/exceptions/captured.py", line 175, in deco
    raise converted from None
pyspark.errors.exceptions.captured.AnalysisException: [PATH_NOT_FOUND] Path does not exist: file:/opt/airflow/tmp/russian_houses.csv.
[2025-10-02T07:47:47.810+0000] {taskinstance.py:1206} INFO - Marking task as FAILED. dag_id=main, task_id=run_pyspark_task, run_id=manual__2025-10-02T07:47:38.699980+00:00, execution_date=20251002T074738, start_date=20251002T074740, end_date=20251002T074747
[2025-10-02T07:47:47.826+0000] {standard_task_runner.py:110} ERROR - Failed to execute job 53 for task run_pyspark_task ([PATH_NOT_FOUND] Path does not exist: file:/opt/airflow/tmp/russian_houses.csv.; 64)
[2025-10-02T07:47:47.865+0000] {local_task_job_runner.py:240} INFO - Task exited with return code 1
[2025-10-02T07:47:47.882+0000] {taskinstance.py:3503} INFO - 0 downstream tasks scheduled from follow-on schedule check
[2025-10-02T07:47:47.885+0000] {local_task_job_runner.py:222} INFO - ::endgroup::
