[2025-10-02T10:28:58.664+0000] {local_task_job_runner.py:120} INFO - ::group::Pre task execution logs
[2025-10-02T10:28:58.682+0000] {taskinstance.py:2076} INFO - Dependencies all met for dep_context=non-requeueable deps ti=<TaskInstance: main.run_pyspark_postgres manual__2025-10-02T10:28:29.028352+00:00 [queued]>
[2025-10-02T10:28:58.688+0000] {taskinstance.py:2076} INFO - Dependencies all met for dep_context=requeueable deps ti=<TaskInstance: main.run_pyspark_postgres manual__2025-10-02T10:28:29.028352+00:00 [queued]>
[2025-10-02T10:28:58.688+0000] {taskinstance.py:2306} INFO - Starting attempt 1 of 1
[2025-10-02T10:28:58.701+0000] {taskinstance.py:2330} INFO - Executing <Task(PythonOperator): run_pyspark_postgres> on 2025-10-02 10:28:29.028352+00:00
[2025-10-02T10:28:58.706+0000] {warnings.py:112} WARNING - /home/***/.local/lib/python3.12/site-packages/***/task/task_runner/standard_task_runner.py:61: DeprecationWarning: This process (pid=1756) is multi-threaded, use of fork() may lead to deadlocks in the child.
  pid = os.fork()

[2025-10-02T10:28:58.707+0000] {standard_task_runner.py:63} INFO - Started process 1757 to run task
[2025-10-02T10:28:58.707+0000] {standard_task_runner.py:90} INFO - Running: ['***', 'tasks', 'run', 'main', 'run_pyspark_postgres', 'manual__2025-10-02T10:28:29.028352+00:00', '--job-id', '72', '--raw', '--subdir', 'DAGS_FOLDER/main.py', '--cfg-path', '/tmp/tmp1bywy_op']
[2025-10-02T10:28:58.708+0000] {standard_task_runner.py:91} INFO - Job 72: Subtask run_pyspark_postgres
[2025-10-02T10:28:58.747+0000] {task_command.py:426} INFO - Running <TaskInstance: main.run_pyspark_postgres manual__2025-10-02T10:28:29.028352+00:00 [running]> on host 5adecdfd8c83
[2025-10-02T10:28:58.809+0000] {taskinstance.py:2648} INFO - Exporting env vars: AIRFLOW_CTX_DAG_OWNER='***' AIRFLOW_CTX_DAG_ID='main' AIRFLOW_CTX_TASK_ID='run_pyspark_postgres' AIRFLOW_CTX_EXECUTION_DATE='2025-10-02T10:28:29.028352+00:00' AIRFLOW_CTX_TRY_NUMBER='1' AIRFLOW_CTX_DAG_RUN_ID='manual__2025-10-02T10:28:29.028352+00:00'
[2025-10-02T10:28:58.810+0000] {taskinstance.py:430} INFO - ::endgroup::
[2025-10-02T10:29:04.125+0000] {taskinstance.py:441} INFO - ::group::Post task execution logs
[2025-10-02T10:29:04.127+0000] {taskinstance.py:2905} ERROR - Task failed with exception
Traceback (most recent call last):
  File "/home/airflow/.local/lib/python3.12/site-packages/airflow/models/taskinstance.py", line 465, in _execute_task
    result = _execute_callable(context=context, **execute_callable_kwargs)
             ^^^^^^^^^^^^^^^^^^^^^^^^^^^^^^^^^^^^^^^^^^^^^^^^^^^^^^^^^^^^^
  File "/home/airflow/.local/lib/python3.12/site-packages/airflow/models/taskinstance.py", line 432, in _execute_callable
    return execute_callable(context=context, **execute_callable_kwargs)
           ^^^^^^^^^^^^^^^^^^^^^^^^^^^^^^^^^^^^^^^^^^^^^^^^^^^^^^^^^^^^
  File "/home/airflow/.local/lib/python3.12/site-packages/airflow/models/baseoperator.py", line 401, in wrapper
    return func(self, *args, **kwargs)
           ^^^^^^^^^^^^^^^^^^^^^^^^^^^
  File "/home/airflow/.local/lib/python3.12/site-packages/airflow/operators/python.py", line 235, in execute
    return_value = self.execute_callable()
                   ^^^^^^^^^^^^^^^^^^^^^^^
  File "/home/airflow/.local/lib/python3.12/site-packages/airflow/operators/python.py", line 252, in execute_callable
    return self.python_callable(*self.op_args, **self.op_kwargs)
           ^^^^^^^^^^^^^^^^^^^^^^^^^^^^^^^^^^^^^^^^^^^^^^^^^^^^^
  File "/opt/airflow/dags/main.py", line 65, in read_from_postgres
    df = spark.read.jdbc(url=jdbc_url, table="new_table", properties=connection_properties)
         ^^^^^^^^^^^^^^^^^^^^^^^^^^^^^^^^^^^^^^^^^^^^^^^^^^^^^^^^^^^^^^^^^^^^^^^^^^^^^^^^^^
  File "/home/airflow/.local/lib/python3.12/site-packages/pyspark/sql/readwriter.py", line 927, in jdbc
    return self._df(self._jreader.jdbc(url, table, jprop))
                    ^^^^^^^^^^^^^^^^^^^^^^^^^^^^^^^^^^^^^
  File "/opt/spark/spark-3.4.2-bin-hadoop3/python/lib/py4j-0.10.9.7-src.zip/py4j/java_gateway.py", line 1322, in __call__
    return_value = get_return_value(
                   ^^^^^^^^^^^^^^^^^
  File "/home/airflow/.local/lib/python3.12/site-packages/pyspark/errors/exceptions/captured.py", line 169, in deco
    return f(*a, **kw)
           ^^^^^^^^^^^
  File "/opt/spark/spark-3.4.2-bin-hadoop3/python/lib/py4j-0.10.9.7-src.zip/py4j/protocol.py", line 326, in get_return_value
    raise Py4JJavaError(
py4j.protocol.Py4JJavaError: An error occurred while calling o30.jdbc.
: org.postgresql.util.PSQLException: Connection to localhost:5432 refused. Check that the hostname and port are correct and that the postmaster is accepting TCP/IP connections.
	at org.postgresql.core.v3.ConnectionFactoryImpl.openConnectionImpl(ConnectionFactoryImpl.java:303)
	at org.postgresql.core.ConnectionFactory.openConnection(ConnectionFactory.java:51)
	at org.postgresql.jdbc.PgConnection.<init>(PgConnection.java:223)
	at org.postgresql.Driver.makeConnection(Driver.java:465)
	at org.postgresql.Driver.connect(Driver.java:264)
	at org.apache.spark.sql.execution.datasources.jdbc.connection.BasicConnectionProvider.getConnection(BasicConnectionProvider.scala:49)
	at org.apache.spark.sql.execution.datasources.jdbc.connection.ConnectionProviderBase.create(ConnectionProvider.scala:102)
	at org.apache.spark.sql.jdbc.JdbcDialect.$anonfun$createConnectionFactory$1(JdbcDialects.scala:123)
	at org.apache.spark.sql.jdbc.JdbcDialect.$anonfun$createConnectionFactory$1$adapted(JdbcDialects.scala:119)
	at org.apache.spark.sql.execution.datasources.jdbc.JDBCRDD$.getQueryOutputSchema(JDBCRDD.scala:63)
	at org.apache.spark.sql.execution.datasources.jdbc.JDBCRDD$.resolveTable(JDBCRDD.scala:58)
	at org.apache.spark.sql.execution.datasources.jdbc.JDBCRelation$.getSchema(JDBCRelation.scala:241)
	at org.apache.spark.sql.execution.datasources.jdbc.JdbcRelationProvider.createRelation(JdbcRelationProvider.scala:37)
	at org.apache.spark.sql.execution.datasources.DataSource.resolveRelation(DataSource.scala:346)
	at org.apache.spark.sql.DataFrameReader.loadV1Source(DataFrameReader.scala:229)
	at org.apache.spark.sql.DataFrameReader.$anonfun$load$2(DataFrameReader.scala:211)
	at scala.Option.getOrElse(Option.scala:189)
	at org.apache.spark.sql.DataFrameReader.load(DataFrameReader.scala:211)
	at org.apache.spark.sql.DataFrameReader.load(DataFrameReader.scala:172)
	at org.apache.spark.sql.DataFrameReader.jdbc(DataFrameReader.scala:249)
	at java.base/jdk.internal.reflect.NativeMethodAccessorImpl.invoke0(Native Method)
	at java.base/jdk.internal.reflect.NativeMethodAccessorImpl.invoke(NativeMethodAccessorImpl.java:77)
	at java.base/jdk.internal.reflect.DelegatingMethodAccessorImpl.invoke(DelegatingMethodAccessorImpl.java:43)
	at java.base/java.lang.reflect.Method.invoke(Method.java:569)
	at py4j.reflection.MethodInvoker.invoke(MethodInvoker.java:244)
	at py4j.reflection.ReflectionEngine.invoke(ReflectionEngine.java:374)
	at py4j.Gateway.invoke(Gateway.java:282)
	at py4j.commands.AbstractCommand.invokeMethod(AbstractCommand.java:132)
	at py4j.commands.CallCommand.execute(CallCommand.java:79)
	at py4j.ClientServerConnection.waitForCommands(ClientServerConnection.java:182)
	at py4j.ClientServerConnection.run(ClientServerConnection.java:106)
	at java.base/java.lang.Thread.run(Thread.java:840)
Caused by: java.net.ConnectException: Connection refused
	at java.base/sun.nio.ch.Net.pollConnect(Native Method)
	at java.base/sun.nio.ch.Net.pollConnectNow(Net.java:672)
	at java.base/sun.nio.ch.NioSocketImpl.timedFinishConnect(NioSocketImpl.java:547)
	at java.base/sun.nio.ch.NioSocketImpl.connect(NioSocketImpl.java:602)
	at java.base/java.net.SocksSocketImpl.connect(SocksSocketImpl.java:327)
	at java.base/java.net.Socket.connect(Socket.java:633)
	at org.postgresql.core.PGStream.createSocket(PGStream.java:231)
	at org.postgresql.core.PGStream.<init>(PGStream.java:95)
	at org.postgresql.core.v3.ConnectionFactoryImpl.tryConnect(ConnectionFactoryImpl.java:98)
	at org.postgresql.core.v3.ConnectionFactoryImpl.openConnectionImpl(ConnectionFactoryImpl.java:213)
	... 31 more

[2025-10-02T10:29:04.143+0000] {taskinstance.py:1206} INFO - Marking task as FAILED. dag_id=main, task_id=run_pyspark_postgres, run_id=manual__2025-10-02T10:28:29.028352+00:00, execution_date=20251002T102829, start_date=20251002T102858, end_date=20251002T102904
[2025-10-02T10:29:04.155+0000] {standard_task_runner.py:110} ERROR - Failed to execute job 72 for task run_pyspark_postgres (An error occurred while calling o30.jdbc.
: org.postgresql.util.PSQLException: Connection to localhost:5432 refused. Check that the hostname and port are correct and that the postmaster is accepting TCP/IP connections.
	at org.postgresql.core.v3.ConnectionFactoryImpl.openConnectionImpl(ConnectionFactoryImpl.java:303)
	at org.postgresql.core.ConnectionFactory.openConnection(ConnectionFactory.java:51)
	at org.postgresql.jdbc.PgConnection.<init>(PgConnection.java:223)
	at org.postgresql.Driver.makeConnection(Driver.java:465)
	at org.postgresql.Driver.connect(Driver.java:264)
	at org.apache.spark.sql.execution.datasources.jdbc.connection.BasicConnectionProvider.getConnection(BasicConnectionProvider.scala:49)
	at org.apache.spark.sql.execution.datasources.jdbc.connection.ConnectionProviderBase.create(ConnectionProvider.scala:102)
	at org.apache.spark.sql.jdbc.JdbcDialect.$anonfun$createConnectionFactory$1(JdbcDialects.scala:123)
	at org.apache.spark.sql.jdbc.JdbcDialect.$anonfun$createConnectionFactory$1$adapted(JdbcDialects.scala:119)
	at org.apache.spark.sql.execution.datasources.jdbc.JDBCRDD$.getQueryOutputSchema(JDBCRDD.scala:63)
	at org.apache.spark.sql.execution.datasources.jdbc.JDBCRDD$.resolveTable(JDBCRDD.scala:58)
	at org.apache.spark.sql.execution.datasources.jdbc.JDBCRelation$.getSchema(JDBCRelation.scala:241)
	at org.apache.spark.sql.execution.datasources.jdbc.JdbcRelationProvider.createRelation(JdbcRelationProvider.scala:37)
	at org.apache.spark.sql.execution.datasources.DataSource.resolveRelation(DataSource.scala:346)
	at org.apache.spark.sql.DataFrameReader.loadV1Source(DataFrameReader.scala:229)
	at org.apache.spark.sql.DataFrameReader.$anonfun$load$2(DataFrameReader.scala:211)
	at scala.Option.getOrElse(Option.scala:189)
	at org.apache.spark.sql.DataFrameReader.load(DataFrameReader.scala:211)
	at org.apache.spark.sql.DataFrameReader.load(DataFrameReader.scala:172)
	at org.apache.spark.sql.DataFrameReader.jdbc(DataFrameReader.scala:249)
	at java.base/jdk.internal.reflect.NativeMethodAccessorImpl.invoke0(Native Method)
	at java.base/jdk.internal.reflect.NativeMethodAccessorImpl.invoke(NativeMethodAccessorImpl.java:77)
	at java.base/jdk.internal.reflect.DelegatingMethodAccessorImpl.invoke(DelegatingMethodAccessorImpl.java:43)
	at java.base/java.lang.reflect.Method.invoke(Method.java:569)
	at py4j.reflection.MethodInvoker.invoke(MethodInvoker.java:244)
	at py4j.reflection.ReflectionEngine.invoke(ReflectionEngine.java:374)
	at py4j.Gateway.invoke(Gateway.java:282)
	at py4j.commands.AbstractCommand.invokeMethod(AbstractCommand.java:132)
	at py4j.commands.CallCommand.execute(CallCommand.java:79)
	at py4j.ClientServerConnection.waitForCommands(ClientServerConnection.java:182)
	at py4j.ClientServerConnection.run(ClientServerConnection.java:106)
	at java.base/java.lang.Thread.run(Thread.java:840)
Caused by: java.net.ConnectException: Connection refused
	at java.base/sun.nio.ch.Net.pollConnect(Native Method)
	at java.base/sun.nio.ch.Net.pollConnectNow(Net.java:672)
	at java.base/sun.nio.ch.NioSocketImpl.timedFinishConnect(NioSocketImpl.java:547)
	at java.base/sun.nio.ch.NioSocketImpl.connect(NioSocketImpl.java:602)
	at java.base/java.net.SocksSocketImpl.connect(SocksSocketImpl.java:327)
	at java.base/java.net.Socket.connect(Socket.java:633)
	at org.postgresql.core.PGStream.createSocket(PGStream.java:231)
	at org.postgresql.core.PGStream.<init>(PGStream.java:95)
	at org.postgresql.core.v3.ConnectionFactoryImpl.tryConnect(ConnectionFactoryImpl.java:98)
	at org.postgresql.core.v3.ConnectionFactoryImpl.openConnectionImpl(ConnectionFactoryImpl.java:213)
	... 31 more
; 1757)
[2025-10-02T10:29:04.185+0000] {local_task_job_runner.py:240} INFO - Task exited with return code 1
[2025-10-02T10:29:04.197+0000] {taskinstance.py:3503} INFO - 0 downstream tasks scheduled from follow-on schedule check
[2025-10-02T10:29:04.200+0000] {local_task_job_runner.py:222} INFO - ::endgroup::
